2025-08-06 15:35:28,812 - ERROR - Необработанное исключение: NameError: name 'my_in' is not defined
2025-08-06 15:35:28,820 - ERROR - Трассировка стека:
Traceback (most recent call last):
  File "c:\Users\Alex\Competitions_TT_v1.1\main.py", line 1289, in open
    go_to()
    ~~~~~^^
  File "c:\Users\Alex\Competitions_TT_v1.1\main.py", line 2140, in go_to
    my_in.comboBox_secretary.setCurrentText(titles.secretary)
    ^^^^^
NameError: name 'my_in' is not defined
