2025-08-06 11:32:01,014 - ERROR - Необработанное исключение: UnboundLocalError: cannot access local variable 'full_name_with_age' where it is not associated with a value
2025-08-06 11:32:01,016 - ERROR - Трассировка стека:
Traceback (most recent call last):
  File "c:\Users\Alex\Competitions_TT_v1.1\main.py", line 3698, in tab_double_vid
    go_to()
    ~~~~~^^
  File "c:\Users\Alex\Competitions_TT_v1.1\main.py", line 2116, in go_to
    mark = full_name_with_age.find("до")
           ^^^^^^^^^^^^^^^^^^
UnboundLocalError: cannot access local variable 'full_name_with_age' where it is not associated with a value
